<mujoco>   

    <body mocap="true" name="robot0:mocap" pos="1.0 1.0 1.0">
        <geom conaffinity="0" contype="0" pos="0 0 0" rgba="0 0.5 0 0.7" size="0.005 0.005 0.005" type="box"></geom>
        <geom conaffinity="0" contype="0" pos="0 0 0" rgba="0 0.5 0 0.1" size="1 0.005 0.005" type="box"></geom>
        <geom conaffinity="0" contype="0" pos="0 0 0" rgba="0 0.5 0 0.1" size="0.005 1 0.001" type="box"></geom>
        <geom conaffinity="0" contype="0" pos="0 0 0" rgba="0 0.5 0 0.1" size="0.005 0.005 1" type="box"></geom>
    </body>
    
    <light directional="false" castshadow="false" cutoff="90" exponent="1" diffuse="1 1 1" specular="0 0 0" pos="1 0 1.5" dir="-1 0 -2.5"/>
    <geom name="ground" type="plane" material="MatPlane" pos="0 0 -0.925" size="4 4 .05" rgba="0.7 0.6 0.5 1"/>

    <body name="cammount" pos="0.2 0 0.2">
      <joint name="cammount" type="free" limited="false" damping="1"/>
      <camera name="cam4" pos="0.0 0 0.0" euler="0.75 -0.75 2.5" fovy="55" mode="fixed"/>
      <inertial pos="0 0 0" mass="0.00001"  diaginertia="1 1 1"/>
    </body>
    
    <body name="base" pos="0 0 0">
        <inertial pos="0 0 0" mass="10" diaginertia="0.001 0.001 0.001" />
        <body name="collision_head_link_1" pos="0.11 0 0.75">
            <inertial pos="0 0 0" mass="0.0001" diaginertia="1e-008 1e-008 1e-008" />
            <geom type="sphere" size="0.22" rgba="0.8 0.3 0.3 0.3" pos="-0.07 -0.04 0" />
        </body>
        <body name="collision_head_link_2" pos="0.11 0 0.75">
            <inertial pos="0 0 0" mass="0.0001" diaginertia="1e-008 1e-008 1e-008" />
            <geom type="sphere" size="0.001" rgba="0.8 0.3 0.3 0.3" pos="0 0 0" />
            <geom type="sphere" size="0.22" rgba="0.8 0.3 0.3 0.3" pos="-0.07 0.04 0" />
        </body>
        <body name="torso" pos="0 0 0">
          <camera name="cam0" pos="0.5 0 1.5" euler="0.0 0.0 1.57" fovy="45" mode="fixed"/>
            
            <inertial pos="0 0 0" quat="0.997433 0.00167178 0.0715546 -0.00209003" mass="35.3365" diaginertia="1.87139 1.66268 0.779991" />
                      
            
            <body name="left_arm_mount" pos="0.024645 0.219645 0.118588" quat="0.923879 0 0 0.382684">
                <inertial pos="0 0 0" mass="0.0001" diaginertia="1e-008 1e-008 1e-008" />
                <body name="left_upper_shoulder" pos="0.055695 0 0.011038">
                    <inertial pos="0.01783 0.00086 0.19127" quat="0.975667 0.0673303 -0.206117 0.0325173" mass="5.70044" diaginertia="0.0498344 0.0377511 0.0331351" />
                    <joint name="left_s0" type="hinge" pos="0 0 0" axis="0 0 1" range="-1.70168 1.70168"/><!-- maxvel="1.5" />-->
                    <geom type="cylinder" size="0.06 0.1361" rgba="0.5 0.1 0.1 1" pos="0 0 0.1361" />
                    <body name="left_lower_shoulder" pos="0.069 0 0.27035" quat="0.707107 -0.707107 0 0">
                        <inertial pos="0.06845 0.00269 -0.00529" quat="0.447487 0.536948 0.56425 0.439391" mass="3.22698" diaginertia="0.0278991 0.0212327 0.0112937" />
                        <joint name="left_s1" type="hinge" pos="0 0 0" axis="0 0 1" range="-2.147 1.047"/><!-- maxvel="1.5" />-->
                        <geom type="cylinder" size="0.06 0.06" rgba="0.5 0.1 0.1 1" pos="0 0 0" />
                        <body name="left_upper_elbow" pos="0.102 0 0" quat="0.5 0.5 0.5 0.5">
                            <inertial pos="-0.00276 0.00132 0.18086" quat="0.838995 -0.0423128 -0.121287 0.52876" mass="4.31272" diaginertia="0.0287695 0.0273625 0.011409" />
                            <joint name="left_e0" type="hinge" pos="0 0 0" axis="0 0 1" range="-3.05418 3.05418"/><!-- maxvel="1.5" />-->
                            <geom type="cylinder" size="0.03 0.0535" rgba="0.5 0.1 0.1 1" pos="0 0 -0.0535" />
                            <geom name="left_upper_elbow_visual" type="cylinder" size="0.03 0.1365" pos="0 0 0.1365" />
							
							<body name="left_lower_elbow" pos="0.069 0 0.26242" quat="0.5 -0.5 -0.5 -0.5">
                                <inertial pos="0.02611 0.00159 -0.01117" quat="0.440433 0.577149 0.562777 0.395221" mass="2.07206" diaginertia="0.0132096 0.00950002 0.00685697" />
                                <joint name="left_e1" type="hinge" pos="0 0 0" axis="0 0 1" range="-0.05 2.618"/><!-- maxvel="1.5" />-->
                                <geom type="cylinder" size="0.06 0.05" rgba="0.5 0.1 0.1 1" pos="0 0 0" />
                                <body name="left_upper_forearm" pos="0.10359 0 0" quat="0.5 0.5 0.5 0.5">
                                    <inertial pos="-0.00168 0.0046 0.13952" quat="0.892709 -0.0256256 0.00446984 0.449882" mass="2.24665" diaginertia="0.016916 0.0165511 0.00371123" />
                                    <joint name="left_w0" type="hinge" pos="0 0 0" axis="0 0 1" range="-3.059 3.059"/><!-- maxvel="4" />-->
                                    <geom type="cylinder" size="0.03 0.044" rgba="0.5 0.1 0.1 1" pos="0 0 -0.044" />
									<geom name="left_upper_forearm_visual" type="cylinder" size="0.03 0.136" pos="0 0 0.136" />

                                    <!--<body name="left_arm_itb" pos="-0.0565 0 0.12" quat="0.5 -0.5 -0.5 0.5">
                                        <inertial pos="0 0 0" mass="0.0001" diaginertia="1e-008 1e-008 1e-008" />
                                    </body>-->
                                    <body name="left_lower_forearm" pos="0.01 0 0.2707" quat="0.5 -0.5 -0.5 -0.5">
                                        <inertial pos="0.06041 0.00697 0.006" quat="0.456911 0.468526 0.475683 0.587743" mass="1.60979" diaginertia="0.00708828 0.00552689 0.00379383" />
                                        <joint name="left_w1" type="hinge" pos="0 0 0" axis="0 0 1" range="-1.5708 2.094"/><!-- maxvel="4" />-->
                                        <geom type="cylinder" size="0.06 0.05" rgba="0.5 0.1 0.1 1" pos="0 0 0" />
                                        <body name="left_wrist" pos="0.115975 0 0" quat="0.5 0.5 0.5 0.5">
                                            <inertial pos="0.00198 0.00125 0.01855" quat="0.0594843 0.68926 -0.16016 0.704082" mass="0.35093" diaginertia="0.0003082 0.000269928 0.000251035" />
                                            <joint name="left_w2" type="hinge" pos="0 0 0" axis="0 0 1" range="-3.059 3.059"/><!-- maxvel="4" />-->
                                            <geom type="cylinder" size="0.03 0.0825" rgba="0.1 0.1 0.1 1" pos="0 0 0" />
                                            <body name="left_hand" pos="0 0 0.11355">
                                                <inertial pos="0.01093 0.00042 -0.01532" quat="0.025365 0.814618 0.0196357 0.579109" mass="0.19125" diaginertia="0.000246058 0.000211549 0.000167391" />
                                                <geom type="cylinder" size="0.04 0.0232" pos="0 0 -0.0232" />
                                                

                                                <body name="left_gripper_base" pos="0 0 0.025">
                                                    <site name="grip" pos="0.0 0 0" rgba="1 0 0 1" size="0.02 0.02 0.02"/>
                                                    <inertial pos="0 0 0" quat="-0.5 0.5 0.5 0.5" mass="0.3" diaginertia="3e-08 2e-08 2e-08" />
                                        
                                                    <geom size="0.029 0.05" quat="0 0 0.707107 0.707107" type="cylinder" />
                                                    
                                                    <body name="l_gripper_l_finger" pos="0 -0.0015 0.02">
                                                        
                                                        <inertial pos="0 0 0" quat="0 0 0 -1" mass="0.02" diaginertia="0.01 0.01 0.01" />
                                                        <!-- <joint name="l_gripper_l_finger_joint" pos="0 0 0" axis="0 1 0" type="slide" range="0 0.04"/> -->

                                                        <geom size="0.005 0.00675 0.05635" pos="0 0.01725 0.0615" quat="0 0 0 -1" type="box" rgba="0.1 0.1 0.1 1"/>
                                                        <geom size="0.005 0.025 0.0085" pos="-0.005 -0.003 0.0083" quat="0 0 0 -1" type="box" rgba="0.1 0.1 0.1 1"/>
                                                        <body name="l_gripper_l_finger_tip" pos="0 0.01725 0.1127">
                                                            <site name="grip_l" pos="0.0 0.0 0" rgba="0 1 0 1" size="0.01 0.01 0.01"/>
                                                            <inertial pos="0 0 0" quat="0 0 0 1" mass="0.01" diaginertia="0.01 0.01 0.01" />
                                                            
                                                            <!-- paddle tip  -->
                                                            <!-- <geom size="0.021 0.00325 0.0185" pos="0 -0.0045 -0.015" quat="0 0 0 1" type="box" /> -->
                                                            
                                                            <!-- half round tip -->
                                                            <geom size="0.008 0.0185" pos="0 -0.0045 -0.015" quat="0 0 0 1" type="cylinder" />
                                                        </body>
                                                    </body>
                                                     <body name="l_gripper_r_finger" pos="0 0.0015 0.02">
                                                        <inertial pos="0 0 0" mass="0.02" diaginertia="0.01 0.01 0.01" />
                                                        <!-- <joint name="l_gripper_r_finger_joint" pos="0 0 0" axis="0 1 0" type="slide" range="-0.04 0"/> -->
                                                        <!-- extended narrow finger-->
                                                        
                                                        <geom size="0.005 0.00675 0.05635" pos="0 -0.01725 0.0615" type="box" rgba="0.1 0.1 0.1 1"/>
                                                        <geom size="0.005 0.025 0.0085" pos="0.005 0.003 0.0083" type="box" rgba="0.1 0.1 0.1 1"/>
                                                        <body name="l_gripper_r_finger_tip" pos="0 -0.01725 0.1127">
                                                            <site name="grip_r" pos="0.0 0.0 0" rgba="0 1 0 1" size="0.01 0.01 0.01"/>
                                                            <inertial pos="0 0 0" mass="0.01" diaginertia="0.01 0.01 0.01" />
                                                            <!-- paddle tip -->
                                                            <!-- <geom size="0.021 0.00325 0.0185" pos="0 0.0045 -0.015" type="box" /> -->
                                                            <!-- half round tip -->
                                                            <geom size="0.008 0.0185" pos="0 0.0045 -0.015" type="cylinder" />
                                                        </body>
                                                    </body> 
                                                </body>
                                            </body>
                                        </body>
                                    </body>
                                </body>
                            </body>
                        </body>
                    </body>
                </body>
            </body>
        </body>
    </body>

    
    <!-- Table -->
    <body name="top" pos="0.6 0.0 -0.05">
        <geom name="top" rgba="0.8 0.8 0.8 1" material="tabletop1" type="box" size="0.4 0.8 0.02" contype="1" conaffinity="1" friction="1 0.005 0.0001"/>
        
        <!-- leg 1 -->
        <body name="leg1" pos="0.19 0.49 -0.35">
            <geom name="leg1" rgba="0.2 0.2 0.2 1" type="box" size="0.01 0.01 0.35" contype="2" conaffinity="2" />
        </body>

        <!-- leg 2 -->
        <body name="leg2" pos="0.19 -0.49 -0.35">
            <geom name="leg2" rgba="0.2 0.2 0.2 2" type="box" size="0.01 0.01 0.35" contype="2" conaffinity="2" />
        </body>

        <!-- leg 3 -->
        <body name="leg3" pos="-0.19 0.49 -0.35">
            <geom name="leg3" rgba="0.2 0.2 0.2 3" type="box" size="0.01 0.01 0.35" contype="1" conaffinity="1" />
        </body>

        <!-- leg 4 -->
        <body name="leg4" pos="-0.19 -0.49 -0.35">
            <geom name="leg4" rgba="0.2 0.2 0.2 4" type="box" size="0.01 0.01 0.35" contype="1" conaffinity="1" />
        </body>

    </body>
    
</mujoco>
